downloads:
  failures:
  - behaviorType: throwExceptionProcessing
    extended_debug: "Traceback (most recent call last):\n  File \"/home/glop102/git/RSSTorrentAutomator/./threads/downloads/__init__.py\"\
      , line 79, in __downloads_thread_main_loop\n    process.process(__hosts,item,__downloads_stop_flag)\n\
      \  File \"/home/glop102/git/RSSTorrentAutomator/./threads/downloads/debug.py\"\
      , line 39, in process\n    raise Exception(\"Debug Exception raised in process()\"\
      )\nException: Debug Exception raised in process()\n"
    fail count: 3
    host: This is debug, so no host
    reason: Debug Exception raised in process()
    taskType: debug
  hosts:
    whatbox:
      hostname: giotto.whatbox.ca
      protocol: sftp
  queue: []
